#include <filesystem>

#include <boost/algorithm/string/predicate.hpp>
#include <boost/filesystem.hpp>

#include <fmt/color.h>

#include <jank/util/mapped_file.hpp>
#include <jank/util/scope_exit.hpp>
#include <jank/read/lex.hpp>
#include <jank/read/parse.hpp>
#include <jank/runtime/obj/number.hpp>
#include <jank/runtime/obj/vector.hpp>
#include <jank/runtime/obj/string.hpp>
#include <jank/runtime/obj/keyword.hpp>
#include <jank/analyze/processor.hpp>
#include <jank/jit/processor.hpp>

#include <clang/Interpreter/Interpreter.h>

/* This must go last; doctest and glog both define CHECK and family. */
#include <doctest/doctest.h>

namespace jank::jit
{
  struct failure
  {
    boost::filesystem::path path;
    native_string error;
  };

  TEST_CASE("Files")
  {
    jit::processor jit_prc;
    runtime::context rt_ctx;
    auto const cardinal_result(rt_ctx.intern_keyword(runtime::obj::symbol{ "", "success" }, true));
    rt_ctx.eval_prelude(jit_prc);
    size_t test_count{};

    /* The functionality I want here is too complex for doctest to handle. Output should be
     * swallowed for expected scenarios, including expected failures, but the output should
     * be shown whenever something unexpected happens, so it can be debugged. On top of that,
     * individual failures being reported would be helpful. Thus all the manual tracking in
     * here. The outcome is nice, though. */
    native_vector<failure> failures;

    for(auto const &dir_entry : boost::filesystem::recursive_directory_iterator("test/jank"))
    {
      if(!boost::filesystem::is_regular_file(dir_entry.path()))
      { continue; }

      auto const expect_success
      (boost::algorithm::starts_with(dir_entry.path().filename().string(), "pass-"));
      auto const expect_failure
      (boost::algorithm::starts_with(dir_entry.path().filename().string(), "fail-"));
      auto const allow_failure
      (boost::algorithm::starts_with(dir_entry.path().filename().string(), "warn-"));
      CHECK_MESSAGE
      (
        (expect_success || expect_failure || allow_failure),
        "Test file needs to begin with pass- or fail- or warn-: ",
        dir_entry
      );
      ++test_count;

      runtime::context test_rt_ctx{ rt_ctx };
      bool passed{ true };
      std::stringstream captured_output;

      fmt::print("testing file {} => ", dir_entry.path().string());

      try
      {
        /* Silence ouptut when running these. This include compilation errors from Cling, since we're
         * going to intentionally make that happen. */
        std::streambuf * const old_cout{ std::cout.rdbuf(captured_output.rdbuf()) };
        std::streambuf * const old_cerr{ std::cerr.rdbuf(captured_output.rdbuf()) };
        util::scope_exit const _
        {
          [=]()
          {
            std::cout.rdbuf(old_cout);
            std::cerr.rdbuf(old_cerr);
          }
        };

        auto const result(test_rt_ctx.eval_file(dir_entry.path().string(), jit_prc));
        if(!expect_success)
        {
          failures.push_back
          (
            {
              dir_entry.path(),
              fmt::format
              (
                "Test failure was expected, but it passed with {}",
                (result == nullptr ? "nullptr" : result->to_string())
              )
            }
          );
          passed = false;
        }
        else
        {
          if(result == nullptr)
          {
            failures.push_back({ dir_entry.path(), "Returned object is null" });
            passed = false;
          }
          else if(!result->equal(cardinal_result))
          {
            failures.push_back
            ({ dir_entry.path(), fmt::format("Result is not :success: {}", result->to_string()) });
            passed = false;
          }
        }
      }
      catch(std::exception const &e)
      {
        if(expect_success)
        {
          failures.push_back({ dir_entry.path(), fmt::format("Exception thrown: {}", e.what()) });
          passed = false;
        }
      }
      catch(...)
      {
        if(expect_success)
        {
          failures.push_back({ dir_entry.path(), "Unknown exception thrown" });
          passed = false;
        }
      }

      if(allow_failure)
      { fmt::print(fmt::fg(fmt::color::orange), "allowed failure\n"); }
      else if(passed)
      { fmt::print(fmt::fg(fmt::color::green), "success\n"); }
      else
      {
        fmt::print(fmt::fg(fmt::color::red), "failure\n");
        std::cerr << captured_output.rdbuf() << std::endl;
      }
    }

    CHECK(failures.empty());
    for(auto const &f : failures)
    {
      fmt::print
      (
        "{}: {} {}\n",
        fmt::styled("failure", fmt::fg(fmt::color::red)),
        f.path.string(),
        f.error
      );
    }
    fmt::print("tested {} jank files\n", test_count);
  }
}
